Workbook
Name ServiceCompany: [1]申請書・サービス提供会社マスタ!$A$3:$A$48
Name Version: マスタ!$E$2
Name インフラ環境: マスタ!$A$2:$A$11
Name リスクレベル: 検査結果!$A$19:$A$23
Name 祝日: #REF!
Name 祝日: マスタ!#REF!
Name 所属: マスタ!$C$2:$C$24
Name 要対策: 検査結果!$A$19:$A$21

Sheet FAQ
A1: よくある質問
A3: Q. 検査の目的や観点を教えてほしい。
A4: A. 検査案内時に添付した検査概要資料にて紹介しています。ご参照ください。
A6: Q. 検査の実施前に本番環境にリリースしてもよいのでしょうか。
A7: A. 本検査はリリースの許可を与えるためのものではありませんので、検査完了までリリースを控えていただく必要性はございません。
A9: Q. 検査の実施前に別案件の改修を検証環境にリリースしてもよいのでしょうか。
A10: A. 基本的にこちらからのリリースに制限はございませんが、導線・動作の変更があるようでしたらその内容をご連絡ください。
A12: Q. 外部のシステム（ベンダー）を使用しているが、本ファイルを外部ベンダーに共有・記載してもらうことは可能か。
A13: A. 本ファイルを外部ベンダーに共有・記載いただくことに問題はありません。
A15: Q. 外部のシステム（ベンダー）を使用しているが、検査を実施するのか。
A16: A. 原則、インターネットに公開し、カスタマー個人情報を保有するすべてのシステム（ASPを含む）は検査対象となります。
A18: Q. 外部のシステムを使用していて、前回検査時に検査実施不可と回答しているのに何故また検査依頼が来ているのか。
... A39: 本検査においてはご担当者様やサイト、サービスごとの管理はしておりませんので、お手数をおかけいたしますが、各案件それぞれに対してご対応および情報提供をお願いいたします。

Sheet 基本情報
A1: Web脆弱性検査ヒアリングシート | F1: =Version -> Ver.7.2
A3: Webアプリ脆弱性検査の実施にあたり、以下情報のご確認、ご提供をお願いします。
A4: ・基本情報（検査対象、連絡先）
A5: ・システム情報（インフラ環境など）
A6: ・検査情報（検査用URL、アカウントなど）
A7: ・検査における禁止事項 ＜「禁止操作」シートにご記載ください。＞
A8: 黄色背景色 のセルの内容を確認・記載ください。
A10: ■検査対象：リスクレビュー申請書から転記しているものもあります。申請時から変更あれば更新してください。
A11: 項目 | C11: 説明・記載例 | D11: 記入・確認欄
A12: 案件名 | C12: リスクレビュー申請時の案件名です。 | D12: RISCORCL-18362 HR Miitel要約のMypage自動反映
A13: 区分 | C13: 当該サービスが新規か既存かをお答えください。 | D13: 既存サイトにページ・機能追加
A14: サービス名 | C14: サービス名が正しいかご確認ください。 | D14: リクルートエージェント
A15: 企画概要 | C15: リスクレビュー依頼内容をご確認ください。 | D15: *前提*_x000D_ Miitelでの録音、録音されたデータを生成AIで要約を生成しCSにデリバリーする施策はすでに実施済み_x000D_ 本施策では要約生成のCS表出方法のみ変更する_x000D_ *案件概要*_x000D_ * 要約自動反映_x000D_ ** 生成された要約をCSのMypageに自動反映する_x000D_ * CS通知_x000D_ ** 要約Mypage反映後、CSがPDTにログインした際にモーダルにて、要約が生成・反映されたことを通知通知する_x000D_ * 要約確認_x000D_ ** Mypageに要約確認セクションを新設し、要約内容を確認できるようにする_x000D_ * 要約反映_x000D_ ** 要約上の「レジュメに反映する」ボタンを押下すると、CSがすでにレジュメに入力している職務要約・業務内容の内容と、MiiTelにて生成された要約内容が表示される_x000D_ ** 「反映する」ボタンを押下すると、要約内容がレジュメに直接反映される_x000D_ * CA通知_x000D_ ** Mypageに反映された要約は、コミュでささる（コミュ内容は既存から変更なし）_x000D_ * CSからのFB改修_x000D_ ** モーダル形式にて「一部修正が必要だった」「そのまま採用した」「全く利用できなかった」ボタンを表示し、CSからのFBを回収する_x000D_ *その他（ASISとの差分）*_x000D_ * MiiTelを用いた要約生成については[https://r-std-proc.atlassian.net/browse/RCAPROC-14957|https://r-std-proc.atlassian.net/browse/RCAPROC-14957|smart-link] にて標プロ完了している_x000D_ * 現状は要約生成後、生成内容がCAに通知され、CAがチェック・編集した後にメールにてCSへ送付している_x000D_ * 今回の案件では、要約生成後CAチェック・編集を通さずに直接CSへ送付（Mypage上での要約反映）がされること、さらにMypageからレジュメへ直接反映が可能となる点が差分となる_x000D_ * [システムフロー図|https://www.figma.com/board/qCRh2dE8x827PxQn9Kw8Gu/MiiTel%E6%A5%AD%E5%8B%99%E3%82%B7%E3%82%B9%E3%83%86%E3%83%A0%E3%83%95%E3%83%AD%E3%83%BC?node-id=2920-12845&t=ZjVrmkIoaW2iKwAm-0]_x000D_ * [^MiiTel要約レシ゛ュメ反映_ユーサ゛ーフロー.pdf] _x000D_ * 免責：[https://docs.google.com/document/d/1xMTh957xsB2ygcz9uDBzQ7BkVQUkc4XrHRE6QtjZDDY/edit?tab=t.0#heading=h.dji279emetb|https://docs.google.com/document/d/1xMTh957xsB2ygcz9uDBzQ7BkVQUkc4XrHRE6QtjZDDY/edit?tab=t.0#heading=h.dji279emetb|smart-link]
A16: C/O予定日 | C16: 当該サービスのC/O予定日をご確認ください。 | D16: 45749
A18: ■連絡先：検査に関する連絡先をご記載ください。（二名以上の方と連絡が取れるようにしてください。）
A19: 担当 | B19: 所属 | C19: 部署 | D19: 氏名 <メールアドレス＞ | E19: 電話番号 | F19: 宛先
A20: 企画 | B20: RTC | C20: ＩＴソリ統括ＣＳＥ部ＱＭＧ | D20: 陸 瑠宇土 <riku_root@r.recruit.co.jp> | E20: 070-7777-7777 | F20: TO
C21: Placementプロダクトデザイン2G | D21: 松田 郁代奈<iyona_matsuda@r.recruit.co.jp>
C22: Placementプロダクトデザイン2G | D22: 松村草也<soya_matsumura@r.recruit.co.jp>
C23: Placementプロダクトデザイン1G | D23: 森山真幸<01033081@r.recruit.co.jp>
A26: ※検査開始までの調整、検査の開始・終了連絡、検査結果通知（脆弱性情報を含んでいます）などのご連絡先として使用します。
A28: ■システム情報
A29: 項目 | C29: 説明・記載例 | D29: 記入・確認欄
A30: インフラ環境 | C30: サービスを提供しているインフラ環境をお答えください。 | D30: Rクラウド
A31: インフラ補足 | C31: インフラに「その他リクルート環境」、「社外インフラ」、「ASP」を利用、もしくは複合環境（○○と××）の場合、その詳細をお答えください。
A32: 開発ベンダー | C32: Webアプリ開発を委託したベンダー（パートナー）名をお答えください。 自社、Rグループ内を含めて、全て明記してください。 記載例）RTC、株式会社○○開発 | D32: RCL, NTTD, FPT
A33: 開発言語 | C33: Webアプリ開発に使用された言語をお答えください。 不明な場合は未記入で問題ございません。 記載例）PHP、Java | D33: Javascript（React/Next.js）・Kotlin
A34: データベース | C34: Webアプリ開発に使用されたデータベースをお答えください。 不明な場合は未記入で問題ございません。 記載例）MySQL、PostgreSQL | D34: Oracle
A35: アクセス制限 | C35: 本番環境にネットワークレベルのアクセス制限の有り無し、ある場合はその方式を明記してください。 記載例） クライアントWeb：クライアント端末認証あり R管理：リクルート標準環境からのみアクセス可能とするIP制限あり | D35: ネットワークレベルのアクセス制限無し
A37: ■検査情報
A38: 項目 | C38: 説明・記載例 | D38: 記入・確認欄
A39: 検査実施予定日 | C39: ご都合がつかない場合、早めにご連絡ください。 | D39: 45765
A40: 検査を実施する環境 | C40: 検査を実施する環境について選択してください。 原則、開発環境のご用意をお願いしております。
A41: 検査用URL | C41: 検査で使用する開発環境・検証環境のURLを記載してください。 やむを得ず本番環境を使用する場合は本番環境URLの欄にご記載ください。 記載例）CS：カスタマー、CL：クライアント、RM：R管理、SD：スマデ、OT：その他 CS https://wwwtest.hogehoge.jp/ CL 本番利用 | D41: https://it02.mypage.r-agent.com/
D42: http://（開発・検証環境）
D43: http://（開発・検証環境）
D44: http://（開発・検証環境）
B46: 本番環境URL | C46: 検査の安全性を確保するため、本番環境のURLを任意でご記載ください。 検査で本番環境を使用するサイトは必須でご記載ください。 記載例）CS：カスタマー、CL：クライアント、RM：R管理、SD：スマデ、OT：その他 CS https://www.hogehoge.jp/ SD https://www.sd.hogehoge.jp/ | D46: http://（本番環境）
D47: http://（本番環境）
D48: http://（本番環境）
...

Sheet 基本情報_old
A1: Webアプリ脆弱性検査ヒアリングシート
A3: Webアプリ脆弱性検査の実施にあたり、以下情報のご確認、ご提供をお願いします。
A4: ・基本情報（検査対象、連絡先）
A5: ・システム情報（インフラ環境など）
A6: ・検査情報（検査用URL、アカウントなど）
A7: ・検査における禁止事項 ＜「禁止操作」シートにご記載ください。＞
A9: ■検査対象：Webサイトレビュー申請書から転記しているものもあります。申請時から変更あれば更新してください。
A10: 案件名 | C10: Webサイトレビュー申請時の案件名です。
A11: 区分 | C11: 当該サービスが新規か既存かをお答えください。
A12: サービス名 | C12: サービス名が正しいかご確認ください。
A13: 企画概要 | C13: Webサイトレビュー依頼内容をご確認ください。
A14: C/O予定日 | C14: 当該サービスのC/O予定日をご確認ください。
A16: ■連絡先：検査に関する連絡先をご記載ください。（二名以上の方と連絡が取れるようにしてください。）
A17: 担当 | B17: 氏名 <メールアドレス＞ | C17: 電話番号 | D17: 所属 | E17: 部署
A18: 企画 | B18: 陸 瑠宇土 <riku_root@r.recruit.co.jp> | C18: 070-7777-7777 | D18: RTC | E18: ＩＴソリ統括ＣＳＥ部ＱＭＧ
A19: 企画
A20: システム
A21: スマホアプリ
A24: ※検査開始までの調整、検査の開始・終了連絡、検査結果通知（脆弱性情報を含んでいます）などのご連絡先として使用します。
A26: ■システム情報
A27: インフラ環境 | C27: サービスを提供しているインフラ環境をお答えください。
A28: インフラ補足 | C28: インフラに「その他リクルート環境」、「社外インフラ」、「ASP」を利用の場合、その詳細をお答えください。
A29: 開発ベンダー | C29: Webアプリ開発を委託したベンダー（パートナー）名をお答えください。 自社、Rグループ内を含めて、全て明記してください。 記載例）RTC、株式会社○○開発
A30: スマホアプリ | C30: スマホアプリがある場合、アプリの提供方法を明記してください。 記載例） アプリ名称：リクルートアプリ iPhoneのみ対応 入手先：https://itunes.apple.com/jp/app/hoge 2018/1/10リリース
A31: アクセス制限 | C31: 本番環境にネットワークレベルのアクセス制限があれば明記してください。 記載例） クライアントWeb：クライアント端末認証あり R管理：リクルート標準環境からのみアクセス可能とするIP制限あり
A33: ■検査情報
A34: 検査実施予定日 | C34: ご都合がつかない場合、早めにご連絡ください。
A35: 検査用URL | B35: カスタマー：http:// クライアント：http:// R管理：http:// スマホ：http:// | C35: やむを得ず本番環境を使用する場合は明示してください。 記載例） カスタマー：https://wwwtest.hogehoge.jp/ スマホ：https://www.sd.hogehoge.jp/ 本番環境
A36: アクセス条件 | C36: 検査用URLへの接続にBasic認証等の必要があれば明記してください。 IP制限については、下記検査元IPを許可してください。 XXX.XXX.XXX.XXX、XXX.XXX.XXX.XXX、XXX.XXX.XXX.XXX 記載例）要Basic認証：ID/PASS：hoge/Z1hG87uR
A37: 検査用アカウント （カスタマー） | B37: hoge01@waku-2.com Pass：xxxxx hoge02@waku-2.com Pass：xxxxx hoge03@waku-2.com Pass：xxxxx | C37: 検査側にて作成可能であれば、作成方法をご教示ください。 検査側にて作成不可であれば、２～３個のアカウントをご提供ください。 登録に際してメールアドレスが必要な場合、左記のものをご使用ください。 記載例） 作成可能：http://～～～/regist 参照 作成不可：hoge01 ～ hoge03 Pass：hogehoge
A38: 検査用アカウント （クライアント/ 社内） | B38: hoge01@waku-2.com Pass：xxxxx hoge02@waku-2.com Pass：xxxxx hoge03@waku-2.com Pass：xxxxx hoge04@waku-2.com Pass：xxxxx | C38: 権限ごとに２個ずつのアカウントをご提供ください。 登録に際してメールアドレスが必要な場合、左記のものをご使用ください。 記載例） 一般権限：hoge01、hoge02 Pass：hogehoge 承認権限：hoge03、hoge04 Pass：hogehoge
A39: アカウント ロックアウト | C39: ログイン試行回数制限など、機能制限があれば明記してください。 アカウントロックアウトありの場合は解除の仕様もご教示ください。 記載例） アカウントロックアウトあり 連続失敗３回でロック 30分後に自動解除
A40: その他特記事項 | C40: その他特記事項あればご記載ください。

Sheet 禁止操作
A1: Web脆弱性検査ヒアリングシート
A3: ■禁止操作：別サーバと通信があり課金が発生するなどの理由があって、実施してはいけない操作があれば明記してください。
A4: 例）検査の対象が本番と同一設定となっており、大量のメールやSMSが本番環境に配信されてしまう場合
A5: 検査の対象となる環境と外部のASPが連携されており、大量のメールやSMSが配信され課金が発生する可能性がある場合
A6: ※事前の検査対象画面確認の際にも操作をさせていただきますので、その際を含めて禁止操作をご記入ください。
A8: 画面名 | B8: 会議室予約
A9: URL | B9: http://wwwtest.hogehoge.jp/hoge/
A10: 事由 | B10: 実際の会議室の予約が発生するため
A11: 当該箇所 | B11: ※画面イメージを張り付けて当該箇所を明示してください
A14: 画面名
A15: URL
A16: 事由
A17: 当該箇所
A20: 画面名
A21: URL
A22: 事由
A23: 当該箇所
A26: 画面名
A27: URL
A28: 事由
A29: 当該箇所
... A41: 当該箇所

Sheet 新設・改修対象画面
A1: Web脆弱性検査ヒアリングシート
A3: ■検査対象画面：
A4: 新設サイト・定期検査案件の場合）対象サイト上で、特に検査を希望する画面があれば記載してください。（希望がなければ不要です）
A5: 既存サイト改修案件の場合）対象サイト上の、どの画面に改修を行ったか具体的に共有していただくためのシートです。記載してください。
A7: 該当画面への遷移手順 | B7: 記載例）TOP ＞ ログイン ＞ 問い合わせ ＞ 確認 ＞ 送信 ※ 「送信」を実行する箇所が改修対象です。など
A8: 該当画面①への遷移手順 | B8: TOP > ログイン > マイページ > 確認する
A9: 該当画面②への遷移手順 | B9: TOP > ログイン > マイページ > 確認する > 確認・編集 > レジュメに反映する
A10: 該当画面③への遷移手順
A11: 該当画面④への遷移手順
A13: 該当画面画面名 | B13: 会議室予約
A14: 当該箇所 | B14: ※画面イメージを張り付けて当該箇所を明示してください
A16: 該当画面①画面名 | B16: 要約一覧画面
A17: 該当画面①への遷移手順 | B17: =B8&"" -> TOP > ログイン > マイページ > 確認する
A18: 当該箇所
A20: 該当画面②画面名 | B20: 反映完了画面_職務要約
A21: 該当画面②への遷移手順 | B21: =B9&"" -> TOP > ログイン > マイページ > 確認する > 確認・編集 > レジュメに反映する
A22: 当該箇所
A24: 該当画面③画面名
A25: 該当画面③への遷移手順 | B25: =B10&""
A26: 当該箇所 | B26: ※画面イメージを張り付けて当該箇所を明示してください
A28: 該当画面④画面名
A29: 該当画面④への遷移手順 | B29: =B11&""
A30: 当該箇所 | B30: ※画面イメージを張り付けて当該箇所を明示してください

Sheet 検査結果
A1: Web脆弱性検査結果・対応依頼
A3: 案件名 | B3: =""&基本情報!D12 -> RISCORCL-18362 HR Miitel要約のMypage自動反映
A4: 検査実施日 | B4: 45765
A5: 検査担当者 | B5: 百田 翔
A7: 今回の検査で検出された脆弱性・注意事項を以下の通りご報告いたします。
A8: 下記、対応依頼内容のご対応をお願いします。
A10: ■対応依頼内容
A11: 緊急の脆弱性検出の場合）
A12: ・緊急の脆弱性は、速やかに対応を行うことが望ましいため、先んじてご連絡いたします。
A14: High、Mediumの脆弱性検出の場合）
A15: ・High、Mediumの脆弱性に対し、対応計画を作成し、５営業日以内に送付して下さい。
A17: ■リスクレベル一覧：検出された問題点の深刻度に応じて、対応期限を設定しています。
A18: リスクレベル | B18: 対応期限 | C18: 対応区分
A19: 緊急 | B19: 出来るだけ速やかに | C19: 必須
A20: High | B20: 1ヶ月以内 | C20: 必須
A21: Medium | B21: 3ヶ月以内 | C21: 必須
A22: Low | B22: 任意 ※1 | C22: 任意
A23: - | B23: 任意 ※2 | C23: 任意
A24: ※1 リスクは低いが、脆弱性ではあるので対応することが望ましい
A25: ※2 脆弱性ではないが、攻撃を助長する可能性があるので対応することが望ましい
A27: ■検査結果一覧：検出された問題点（脆弱性、懸念事項）を種類ごとにまとめてレポートしています。
A28: No. | B28: 問題点 | C28: リスクレベル | D28: 個数
A29: 1 | B29: CookieのSecure属性 | C29: - | D29: 1
A30: 2 | B30: クロスサイトリクエストフォージェリ | C30: - | D30: 1
A31: 3 | B31: エラーメッセージ | C31: - | D31: 1
A32: 4 | B32: X-Content-Type-Optionsヘッダの不備 | C32: - | D32: 1
A33: 5
A34: 6
A35: 7
A36: 8
A37: 9
A38: 10
A40: ■検査結果詳細：検出された各問題点の詳細を以下の構成に従って記述しています。
A41: No. | B41: 問題点 | C41: リスクレベル | D41: 個数
A42: 1 | B42: （問題点の概要 一覧と同じものが表示されます）
A44: 想定される被害 | B44: （検出された問題点の影響について記述しています。）
A45: 検出された箇所 | B45: （検出された問題点のURLやパラメータを記述しています。）
A46: 一般的な対策方法 | B46: （検出された問題点を防ぐための一般的な対策方法を記述しています。）
A47: 詳細説明
B48: （フリーフォーマットで問題点の詳細を説明しています。）
...

Sheet 検査画面
A1: Web脆弱性検査実施画面一覧
A3: 案件名 | B3: =""&基本情報!D12 -> RISCORCL-18362 HR Miitel要約のMypage自動反映
A4: 検査実施日 | B4: =検査結果!$B$4 -> 45765
A5: 検査担当者 | B5: =""&検査結果!$B$5 -> 百田 翔
A7: 今回の検査を実施した箇所は以下の画面・操作となります。
A8: 検査結果と併せて確認し、ご対応をお願いします。
A10: ■検査画面一覧：同一画面で異なる操作を検査した場合、同じ画面名が並ぶことがあります。
A11: No. | B11: 画面名 | C11: 脆弱性検出有無
A12: 1 | B12: 確認する | C12: あり
A13: 2 | B13: 反映する | C13: あり
A14: 3 | B14: 反映する | C14: あり
A15: 4 | B15: 反映する | C15: あり
A25: 以下、個別にそのURLと画面キャプチャにて該当箇所を示します。
A27: No. | B27: 画面名 | C27: 脆弱性検出有無
A28: 1 | B28: =""&VLOOKUP($A28,$A$12:$C$25,2,0) -> 確認する | C28: =""&VLOOKUP($A28,$A$12:$C$25,3,0) -> あり
A30: URL | B30: https://it02.mypage.r-agent.com/_next/data/eTV79sOJ4OHNJqIV-5NGQ/interview_summary.json
A31: 当該箇所 | B31: =IF(C30<>"","本画面はパラメータが多いため右欄に記載したもののみ検査しています。","")
A59: No. | B59: 画面名 | C59: 脆弱性検出有無
A60: 2 | B60: =""&VLOOKUP($A60,$A$12:$C$25,2,0) -> 反映する | C60: =""&VLOOKUP($A60,$A$12:$C$25,3,0) -> あり
A62: URL | B62: https://it02.mypage.r-agent.com/api/trpc/rmpLogging.sendLog,features.resume.putCareerSummary?batch=1
A63: 当該箇所 | B63: =IF(C62<>"","本画面はパラメータが多いため右欄に記載したもののみ検査しています。","")
A90: No. | B90: 画面名 | C90: 脆弱性検出有無
A91: 3 | B91: =""&VLOOKUP($A91,$A$12:$C$25,2,0) -> 反映する | C91: =""&VLOOKUP($A91,$A$12:$C$25,3,0) -> あり
A93: URL | B93: https://it02.mypage.r-agent.com/api/trpc/features.notification.checkNewMessage?batch=1&input=%7B%220%22%3A%7B%7D%7D
A95: No. | B95: 画面名 | C95: 脆弱性検出有無
A96: 4 | B96: =""&VLOOKUP($A96,$A$12:$C$25,2,0) -> 反映する | C96: =""&VLOOKUP($A96,$A$12:$C$25,3,0) -> あり
A98: URL | B98: https://it02.mypage.r-agent.com/api/trpc/rmpLogging.sendLog,rmpLogging.sendLog?batch=1

Sheet 対応計画
A1: Web脆弱性検査対応計画
A3: 案件名 | B3: =""&基本情報!D12 -> RISCORCL-18362 HR Miitel要約のMypage自動反映
A4: 記入日
A5: 記載者
A7: 検出されたMedium以上の問題点に対応計画の作成をお願いしています。
A8: 「一般的な対策方法」を参考に、個別に改修方針と対応完了予定日を記載してください。
A10: ■リスクレベル一覧：検出された問題点の深刻度に応じて、対応期限を設定しています。
A11: リスクレベル | B11: 対応期限 | C11: 対応区分
A12: =検査結果!A19 -> 緊急 | B12: =検査結果!B19 -> 出来るだけ速やかに | C12: =検査結果!C19 -> 必須
A13: =検査結果!A20 -> High | B13: =検査結果!B20 -> 1ヶ月以内 | C13: =検査結果!C20 -> 必須
A14: =検査結果!A21 -> Medium | B14: =検査結果!B21 -> 3ヶ月以内 | C14: =検査結果!C21 -> 必須
A16: ■要対策一覧：検出されたMedium以上の問題点に対応計画の作成をお願いしています。
A17: No. | B17: 問題点 | C17: リスクレベル | D17: 個数
A18: 1 | B18: {=IF(OR(検査結果!$C29=要対策),検査結果!B29,"")} | C18: {=IF(OR(検査結果!$C29=要対策),検査結果!C29,"")} | D18: {=IF(OR(検査結果!$C29=要対策),検査結果!D29,"")}
A19: 2 | B19: {=IF(OR(検査結果!$C30=要対策),検査結果!B30,"")} | C19: {=IF(OR(検査結果!$C30=要対策),検査結果!C30,"")} | D19: {=IF(OR(検査結果!$C30=要対策),検査結果!D30,"")}
A20: 3 | B20: {=IF(OR(検査結果!$C31=要対策),検査結果!B31,"")} | C20: {=IF(OR(検査結果!$C31=要対策),検査結果!C31,"")} | D20: {=IF(OR(検査結果!$C31=要対策),検査結果!D31,"")}
A21: 4 | B21: {=IF(OR(検査結果!$C32=要対策),検査結果!B32,"")} | C21: {=IF(OR(検査結果!$C32=要対策),検査結果!C32,"")} | D21: {=IF(OR(検査結果!$C32=要対策),検査結果!D32,"")}
A22: 5 | B22: {=IF(OR(検査結果!$C33=要対策),検査結果!B33,"")} | C22: {=IF(OR(検査結果!$C33=要対策),検査結果!C33,"")} | D22: {=IF(OR(検査結果!$C33=要対策),検査結果!D33,"")}
A23: 6 | B23: {=IF(OR(検査結果!$C34=要対策),検査結果!B34,"")} | C23: {=IF(OR(検査結果!$C34=要対策),検査結果!C34,"")} | D23: {=IF(OR(検査結果!$C34=要対策),検査結果!D34,"")}
A24: 7 | B24: {=IF(OR(検査結果!$C35=要対策),検査結果!B35,"")} | C24: {=IF(OR(検査結果!$C35=要対策),検査結果!C35,"")} | D24: {=IF(OR(検査結果!$C35=要対策),検査結果!D35,"")}
A25: 8 | B25: {=IF(OR(検査結果!$C36=要対策),検査結果!B36,"")} | C25: {=IF(OR(検査結果!$C36=要対策),検査結果!C36,"")} | D25: {=IF(OR(検査結果!$C36=要対策),検査結果!D36,"")}
A26: 9 | B26: {=IF(OR(検査結果!$C37=要対策),検査結果!B37,"")} | C26: {=IF(OR(検査結果!$C37=要対策),検査結果!C37,"")} | D26: {=IF(OR(検査結果!$C37=要対策),検査結果!D37,"")}
A27: 10 | B27: {=IF(OR(検査結果!$C38=要対策),検査結果!B38,"")} | C27: {=IF(OR(検査結果!$C38=要対策),検査結果!C38,"")} | D27: {=IF(OR(検査結果!$C38=要対策),検査結果!D38,"")}
A29: ■対応計画詳細：検出されたMedium以上の各問題点の改修方針と対応完了予定日を記載してください。
A30: No. | B30: 問題点 | C30: リスクレベル | D30: 個数
A31: 1 | B31: （問題点の概要 一覧と同じものが表示されます）
A33: 想定される被害 | B33: （検出された問題点の影響について記述しています。）
A34: 検出された箇所 | B34: （検出された問題点のURLやパラメータを記述しています。）
A35: 一般的な対策方法 | B35: （検出された問題点を防ぐための一般的な対策方法を記述しています。）
A36: 改修方針 | B36: （フリーフォーマットで問題点の改修方針を記載してください。） | C36: 対応完了予定日 | D36: 判定
B38: （記述範囲が足りなければ適宜行を挿入してください。）
A43: No. | B43: 問題点 | C43: リスクレベル | D43: 個数
A44: 1 | B44: =""&VLOOKUP($A44,$A$18:$D$27,2,0) | C44: =""&VLOOKUP($A44,$A$18:$D$27,3,0) | D44: =""&VLOOKUP($A44,$A$18:$D$27,4,0)
A46: 想定される被害 | B46: {=IF(OR($C$44=要対策),""&検査結果!B54,"")}
A47: 検出された箇所 | B47: {=IF(OR($C$44=要対策),""&検査結果!B55,"")}
A48: 一般的な対策方法 | B48: {=IF(OR($C$44=要対策),""&検査結果!B56,"")}
A49: 改修方針 | B49: （フリーフォーマットで問題点の改修方針を記載してください。） | C49: 対応完了予定日 | D49: 判定
A57: No. | B57: 問題点 | C57: リスクレベル | D57: 個数
A58: 2 | B58: =""&VLOOKUP($A58,$A$18:$D$27,2,0) | C58: =""&VLOOKUP($A58,$A$18:$D$27,3,0) | D58: =""&VLOOKUP($A58,$A$18:$D$27,4,0)
A60: 想定される被害 | B60: {=IF(OR($C$58=要対策),""&検査結果!B95,"")}
...

Sheet 再検査
A1: Web脆弱性検査ヒアリングシート＜再検査＞
A3: Web脆弱性検査の再検査実施にあたり、以下情報のご確認、ご提供をお願いします。
A4: ・連絡先情報
A5: ・検査情報（検査用URL、アカウントなど）
A7: ■連絡先：担当者が変更されているようでしたら更新をお願いします。
A8: 担当 | B8: 所属 | C8: 部署 | D8: 氏名 <メールアドレス＞ | E8: 電話番号 | F8: 宛先
A14: ※検査開始までの調整、検査の開始・終了連絡、検査結果通知（脆弱性情報を含んでいます）などのご連絡先として使用します。
A16: ■検査情報：変更されている個所があれば更新をお願いします。
A17: 項目 | C17: 説明・記載例 | D17: 記入・確認欄
A18: 再検査実施予定日 | C18: ご都合がつかない場合、早めにご連絡ください。
A19: 検査用URL | C19: 検査で使用する開発環境・検証環境のURLを記載してください。 やむを得ず本番環境を使用する場合は本番環境URLの欄にご記載ください。 記載例）CS：カスタマー、CL：クライアント、RM：R管理、SD：スマデ、OT：その他 CS https://wwwtest.hogehoge.jp/ CL 本番利用 | D19: http://（開発・検証環境）
D20: http://（開発・検証環境）
D21: http://（開発・検証環境）
D22: http://（開発・検証環境）
B24: 本番環境URL | C24: 検査の安全性を確保するため、本番環境のURLを任意でご記載ください。 検査で本番環境を使用するサイトは必須でご記載ください。 記載例）CS：カスタマー、CL：クライアント、RM：R管理、SD：スマデ、OT：その他 CS https://www.hogehoge.jp/ SD https://www.sd.hogehoge.jp/ | D24: http://（本番環境）
D25: http://（本番環境）
D26: http://（本番環境）
D27: http://（本番環境）
A29: アクセス条件 | C29: =基本情報!C54 -> 検査用URLへの接続にBasic認証等の必要の有り無し、ある場合はその条件等を明記してください。 IP制限については、下記検査元IPを許可してください。 13.112.165.80、153.120.31.228、153.120.31.238、163.43.153.212、210.166.157.210 記載例）要Basic認証：ID/PASS：hoge/Z1hG87uR
A30: スマホアプリ | C30: =基本情報!C55 -> DeployGateもしくはTestflightからの受け渡しが可能な場合は 以下送り先宛に配信をお願いいたします。 【DeployGate送り先】 メールアドレス：kamome_taro_sst001@waku-2.com ユーザ名：web_kensa05 【Testflight送り先】 メールアドレス(AppleID)：kamome_taro_sst003@waku-2.com 氏名：かもめ 三郎 DeployGateもしくはTestflightどちらも不可の場合は、別途ご相談ください。
A31: 検査用アカウント （カスタマー） | C31: =基本情報!C56 -> 検査側にて作成可能であれば、作成方法をご教示ください。 検査側にて作成不可であれば、２～３個のアカウントをご提供ください。 登録に際してメールアドレスが必要な場合、下記のものをご使用ください。 kamome_taro_sst001@waku-2.com kamome_taro_sst002@waku-2.com kamome_taro_sst003@waku-2.com 記載例） 作成可能：http://～～～/regist 参照 作成不可：hoge01 ～ hoge03 Pass：hogehoge
A32: 検査用アカウント （クライアント/社内） | C32: =基本情報!C57 -> 権限ごとに2個ずつのアカウントをご提供ください。 権限を超えた操作を不正に行えないか検証するために使用します。 例）一般権限、管理者権限の2つがあるサイトの場合 ・一般権限のアカウントを2つ 記載例）hoge01、hoge02 Pass：hogehoge ・管理者権限のアカウントを2つ 記載例）hoge03、hoge04 Pass：hogehoge クライアントのアカウントの場合は、異なるクライアントに所属するアカウントをご提供ください。異なるクライアントが所有する情報を、不正に取得・改ざんできないか検証するために使用します。 例）サイト上に複数の組織（組織名hogeと組織名fuga等）が存在する場合（組織＝クライアント） ・組織名hogeのアカウントを2つ ・組織名fugaのアカウントを2つ 登録に際してメールアドレスが必要な場合、下記のものをご使用ください。 kamome_taro_sst004@waku-2.com kamome_taro_sst005@waku-2.com
A33: アカウントロックアウト | C33: アカウントロックアウトの有り無し、ある場合はロックの条件、および解除の仕様をご教示ください。 記載例） アカウントロックアウトあり 連続失敗３回でロック 30分後に自動解除
A34: その他特記事項 | C34: その他特記事項あればご記載ください。

Sheet 再検査結果
A1: Web脆弱性検査結果＜再検査＞
A3: 案件名 | B3: =""&基本情報!D12 -> RISCORCL-18362 HR Miitel要約のMypage自動反映
A4: 再検査実施日
A5: 検査担当者
A7: 改修状況を確認させていただいた結果をご報告いたします。
A8: 結果欄「OK」は脆弱性がなくなっていることを確認できました。
A9: 「NG」は脆弱性が変わらず残っている、あるいは別の脆弱性が検出されております。詳細コメント欄をご確認いただき、再度対応計画をご検討ください。
A11: ■再検査結果一覧：改修済みの問題点に対する再検査の実施状況と結果です。
A12: No. | B12: 問題点 | C12: リスクレベル | D12: 個数 | E12: 確認日 | F12: 結果
A13: 1 | B13: {=IF(OR(検査結果!$C29=要対策),検査結果!B29,"")} | C13: {=IF(OR(検査結果!$C29=要対策),検査結果!C29,"")} | D13: {=IF(OR(検査結果!$C29=要対策),検査結果!D29,"")}
A14: 2 | B14: {=IF(OR(検査結果!$C30=要対策),検査結果!B30,"")} | C14: {=IF(OR(検査結果!$C30=要対策),検査結果!C30,"")} | D14: {=IF(OR(検査結果!$C30=要対策),検査結果!D30,"")}
A15: 3 | B15: {=IF(OR(検査結果!$C31=要対策),検査結果!B31,"")} | C15: {=IF(OR(検査結果!$C31=要対策),検査結果!C31,"")} | D15: {=IF(OR(検査結果!$C31=要対策),検査結果!D31,"")}
A16: 4 | B16: {=IF(OR(検査結果!$C32=要対策),検査結果!B32,"")} | C16: {=IF(OR(検査結果!$C32=要対策),検査結果!C32,"")} | D16: {=IF(OR(検査結果!$C32=要対策),検査結果!D32,"")}
A17: 5 | B17: {=IF(OR(検査結果!$C33=要対策),検査結果!B33,"")} | C17: {=IF(OR(検査結果!$C33=要対策),検査結果!C33,"")} | D17: {=IF(OR(検査結果!$C33=要対策),検査結果!D33,"")}
A18: 6 | B18: {=IF(OR(検査結果!$C34=要対策),検査結果!B34,"")} | C18: {=IF(OR(検査結果!$C34=要対策),検査結果!C34,"")} | D18: {=IF(OR(検査結果!$C34=要対策),検査結果!D34,"")}
A19: 7 | B19: {=IF(OR(検査結果!$C35=要対策),検査結果!B35,"")} | C19: {=IF(OR(検査結果!$C35=要対策),検査結果!C35,"")} | D19: {=IF(OR(検査結果!$C35=要対策),検査結果!D35,"")}
A20: 8 | B20: {=IF(OR(検査結果!$C36=要対策),検査結果!B36,"")} | C20: {=IF(OR(検査結果!$C36=要対策),検査結果!C36,"")} | D20: {=IF(OR(検査結果!$C36=要対策),検査結果!D36,"")}
A21: 9 | B21: {=IF(OR(検査結果!$C37=要対策),検査結果!B37,"")} | C21: {=IF(OR(検査結果!$C37=要対策),検査結果!C37,"")} | D21: {=IF(OR(検査結果!$C37=要対策),検査結果!D37,"")}
A22: 10 | B22: {=IF(OR(検査結果!$C38=要対策),検査結果!B38,"")} | C22: {=IF(OR(検査結果!$C38=要対策),検査結果!C38,"")} | D22: {=IF(OR(検査結果!$C38=要対策),検査結果!D38,"")}
A24: ■再検査結果詳細：再検査結果がNGとなったものについては、その理由と対応予定日をお答えください。
A25: No. | B25: 結果詳細 | C25: 記入者 | D25: NG理由 | E25: 対応予定日
A26: 1
A27: 2
A28: 3
A29: 4
A30: 5
A31: 6
A32: 7
A33: 8
A34: 9
A35: 10
A37: ■再検査結果エビデンス：画像キャプチャ、ログなどを証左として提供しますのでご確認ください。
A38: 脆弱性No.X | B38: に対する追加説明・エビデンス

Sheet マスタ
A1: インフラ環境 | C1: 所属 | E1: 最新 | F1: 更新日 | G1: バージョン | H1: 更新者 | I1: 更新箇所・内容
A2: RAFTEL | C2: RHD(MSSBU) | E2: ="Ver."&VLOOKUP(MAX(F2:F17),F2:G17,2,0) -> Ver.7.2 | F2: 43084 | G2: 6.0 | H2: RTC遠藤 | I2: 大幅リニューアル
A3: RAFTEL改 | C3: RHD(その他) | F3: 43119 | G3: 6.1 | H3: RTC遠藤 | I3: 基本情報 連絡先の担当に入力時メッセージを追加 基本情報 スマホアプリの説明・記載例を微修正 基本情報 アカウント用提供メアドを説明・記載例に移動 入力補助シート作成
A4: RAFTELライト | C4: RCA | F4: 43136 | G4: 6.2 | H4: RTC遠藤 | I4: 検査情報 検査用URLのデフォルトを変更 対応計画 記載者欄が検査結果の検査担当者を参照表示していたのを削除 再検査結果 再検査結果詳細の表頭：詳細コメントを結果詳細に変更 NG理由のコメントを変更 再検査結果エビデンスでの脆弱性毎の区切りサンプルを作成（利用は任意）
A5: RAFTEL改ライト | C5: RCA関連G | F5: 43292 | G5: 6.3 | H5: RTC遠藤 | I5: 基本情報 本番環境URLを追加 基本情報 検査用URLの説明・記載例、デフォルトを変更 再検査 同上箇所 本番URLをブラックリストに登録し、誤って本番を叩かないようにする意図 FAQ 検査終了後連絡について項目追加
A6: HAIJI | C6: RJB | F6: 43623 | G6: 6.４ | H6: RTC並木 | I6: 文言の更新（新規と定期Web脆弱性検査と名称を変更したことに伴い） 「Webサイトレビュー」を「リスクレビュー」に 「Webアプリ脆弱性検査」を「Web脆弱性検査」に
A7: Rクラウド | C7: RJB関連G | F7: 43895 | G7: 6.5 | H7: RTC菱山 | I7: 禁止操作シート＞禁止操作に例を追加
A8: Duranadal | C8: RMS | F8: 44298 | G8: 6.6 | H8: RTC菱山 | I8: ①基本情報に禁止操作に関する項目を追加 ②禁止操作シート＞禁止操作に例を再追加
A9: その他リクルート環境 | C9: RMS関連G | F9: 44732 | G9: 6.7 | H9: RCL菱山 | I9: 検査結果シート（17-18行目）の以下文言削除 Low以上の脆弱性検出の場合） ・脆弱性を修正するにあたり、指摘箇所以外に同様の脆弱性が存在しないか横断的に確認して下さい。
A10: 社外インフラ | C10: RS | F10: 44846 | G10: 6.8 | H10: RCL菱山 | I10: 基本情報シートに以下を追加・変更 追加）開発言語、データベース、検査を実施する環境、検査の対象とするFQDN 変更）検査用アカウント（クライアント/R管理）の説明文修正。 新設・改修対象画面シートの追加。
A11: ASP | C11: RS関連G | F11: 44914 | G11: 6.9 | H11: RCL菱山 | I11: FAQシートの36～39行目を追加。
C12: SS | F12: 45404 | G12: 7.0 | H12: RCL菱山 | I12: ・数式 > 名前の管理よりローカルを参照していた名前を削除 ・『検査結果』の「検査実施日」の書式設定を『基本情報』の「C/O予定日」の書式設定(ユーザー定義)と同様の設定に修正。その他のシートで日付を手動入力する箇所についても同様に修正済み。
C13: SS関連G | F13: 45601 | G13: 7.1 | H13: RCL菱山 | I13: 基本情報シート > 検査用アカウント（クライアント/R管理）の説明文を修正。
C14: RSC | F14: 45603 | G14: 7.2 | H14: RCL菱山 | I14: ①「基本情報」シート A1 Webアプリ脆弱性検査ヒアリングシート 他シートに合わせ、「アプリ」を外す 修正案：Web脆弱性検査ヒアリングシート ②「新設・改修対象画面」シート A1 Web脆弱性検査ヒアリングシート フォントの種類やスタイル、行高さを他シートに合わせる フォントの種類：メイリオ、サイズ：16、スタイル：標準、行高さ：24.75 ③「対応計画」シートの 想定される被害、検出された箇所、一般的な対策方法 のB列内数式について、「要対策」の参照元セルを絶対参照に変更 例） 修正前：{=IF(OR(C44=要対策),""&検査結果!B54,"")} 修正後：{=IF(OR($C$44=要対策),""&検査結果!B54,"")} ④「入力補助」シート 過去案件のファイル名が記入されたままになっており、使用していないためシートごと削除 ※過去案件のファイル名 【業務】180117ゼクシィミーチャ(ゼクシィミーチャ参加者応募フォーム作成)_3（レビュー終了）.xlsm
C15: RSC関連G
C16: RMP
C17: RMP関連G
C18: RLS
C19: RLS関連G
C20: RCO
C21: RTC
C22: RAD
C23: ROS
C24: その他
